Workbook

Sheet TOB
A1: LOCUS | B1: GENE | C1: ANTIBIOTIC | D1: EFFECT | E1: VALUE | F1: TYPE OF MUTATION | G1: OBSERVACIONES | H1: AND01-001 | I1: AND01-004 | J1: AND01-005 | K1: AND01-006 | L1: AND02-001 | M1: AND02-002 | N1: AND02-003 | O1: AND02-006 | P1: AND03-001 | Q1: AND03-003 | R1: AND03-009 | S1: AND03-012 | T1: AND04-001 | U1: AND04-002 | V1: AND04-003 | W1: AND04-004A | X1: AND05-004 | Y1: AND05-005 | Z1: AND05-008 | AA1: AND05-009 | AB1: AND06-001 | AC1: AND06-002 | AD1: AND06-003 | AE1: AND06-006 | AF1: AND07-001 | AG1: AND07-002 | AH1: AND07-003 | AI1: AND07-005 | AJ1: ARA01-001 | AK1: ARA01-002 | AL1: ARA01-003 | AM1: ARA01-006 | AN1: ARA02-001 | AO1: ARA02-002 | AP1: ARA02-005 | AQ1: ARA02-007 | AR1: ARA03-001 | AS1: ARA03-002 | AT1: ARA03-003 | AU1: ARA03-004 | AV1: AST01-001 | AW1: AST01-003 | AX1: AST01-005 | AY1: AST01-006 | AZ1: BAL01-001 | BA1: BAL01-003 | BB1: BAL01-004 | BC1: BAL01-006 | BD1: BAL02-001 | BE1: BAL02-005 | BF1: BAL02-006 | BG1: BAL02-009 | BH1: BAL03-001 | BI1: BAL03-002 | BJ1: BAL03-003 | BK1: BAL03-006 | BL1: BAL04-001 | BM1: BAL04-002 | BN1: BAL04-003 | BO1: BAL04-004 | BP1: CAN01-001 | BQ1: CAN01-002 | BR1: CAN01-003 | BS1: CAN01-004 | BT1: CAT01-001 | BU1: CAT01-004 | BV1: CAT01-005 | BW1: CAT01-007 | BX1: CAT02-001 | BY1: CAT02-002 | BZ1: CAT02-003 | CA1: CAT02-004 | CB1: CAT03-001 | CC1: CAT03-002 | CD1: CAT03-004 | CE1: CAT03-005 | CF1: CAT04-001 | CG1: CAT04-002 | CH1: CAT04-003 | CI1: CAT04-004 | CJ1: CAT05-001 | CK1: CAT05-002 | CL1: CAT05-003 | CM1: CAT05-004 | CN1: CAT06-001 | CO1: CAT06-004 | CP1: CAT06-005 | CQ1: CAT06-008 | CR1: CAT07-001 | CS1: CAT07-002 | CT1: CAT07-003 | CU1: CAT07-005 | CV1: CAT08-013 | CW1: CAT08-014 | CX1: CAT08-015 | CY1: CAT08-016 | CZ1: CAT09-001 | DA1: CAT09-002 | DB1: CAT09-003 | DC1: CAT09-004 | DD1: CLE01-003 | DE1: CLE01-006 | DF1: CLE01-007 | DG1: CLE01-008 | DH1: CLE02-001 | DI1: CLE02-002 | DJ1: CLE02-004 | DK1: CLE02-006 | DL1: CLE03-003 | DM1: CLE03-004 | DN1: CLE03-005 | DO1: CLE03-006 | DP1: CLM01-001 | DQ1: CLM01-002 | DR1: CLM01-003 | DS1: CLM01-004 | DT1: CLM02-004 | DU1: CLM02-005 | DV1: CLM02-013 | DW1: CLM02-014 | DX1: CVA01-001 | DY1: CVA01-002 | DZ1: CVA01-005 | EA1: CVA01-006 | EB1: CVA02-001 | EC1: CVA02-002 | ED1: CVA02-003 | EE1: CVA02-005 | EF1: CVA03-001 | EG1: CVA03-002 | EH1: CVA03-004 | EI1: CVA03-006 | EJ1: EXT01-001 | EK1: EXT01-003 | EL1: EXT01-004 | EM1: EXT01-005 | EN1: GAL01-001 | EO1: GAL01-002 | EP1: GAL01-003 | EQ1: GAL01-012 | ER1: GAL02-001 | ES1: GAL02-002 | ET1: GAL02-004 | EU1: GAL02-006 | EV1: GAL03-002 | EW1: GAL03-003 | EX1: GAL03-004 | EY1: GAL03-005 | EZ1: GAL04-001 | FA1: GAL04-002 | FB1: GAL04-004 | FC1: GAL04-005 | FD1: GAL05-002 | FE1: GAL05-003 | FF1: GAL05-004 | FG1: GAL05-005 | FH1: GAL06-001 | FI1: GAL06-002 | FJ1: GAL06-003 | FK1: GAL06-004 | FL1: ICA01-001 | FM1: ICA01-002 | FN1: ICA01-003 | FO1: ICA01-004 | FP1: LRJ01-002 | FQ1: LRJ01-005 | FR1: LRJ01-010 | FS1: LRJ01-012 | FT1: MAD01-001 | FU1: MAD01-002 | FV1: MAD01-004 | FW1: MAD01-005 | FX1: MAD02-001 | FY1: MAD02-002 | FZ1: MAD02-004 | GA1: MAD02-005 | GB1: MAD03-001 | GC1: MAD03-002 | GD1: MAD03-004 | GE1: MAD03-005 | GF1: MAD04-001 | GG1: MAD04-002 | GH1: MAD04-003 | GI1: MAD04-004 | GJ1: MAD05-003 | GK1: MAD05-008 | GL1: MAD05-009 | GM1: MAD05-011 | GN1: MAD06-001 | GO1: MAD06-002 | GP1: MAD06-004 | GQ1: MAD06-005 | GR1: MUR01-001 | GS1: MUR01-002 | GT1: MUR01-003 | GU1: MUR01-004 | GV1: NAV01-001 | GW1: NAV01-004 | GX1: NAV01-005 | GY1: NAV01-012 | GZ1: PVA01-003 | HA1: PVA01-006 | HB1: PVA01-007 | HC1: PVA01-011
A2: ACQUIRED | B2: aac, aad, ant | C2: TOB | D2: + | E2: 1 | H2: =VC!C54 -> aac(6')-Ic | I2: =VC!D54 -> 0 | J2: =VC!E54 -> 0 | K2: =VC!F54 -> 0 | L2: =VC!G54 -> 0 | M2: =VC!H54 -> 0 | N2: =VC!I54 -> aac(3)-Ib | O2: =VC!J54 -> 0 | ... HC2: =VC!GX54 -> 0
A3: ACQUIRED | B3: blaOXA, blaNDM, blaVIM, blaIMP, blaCTX-M, blaKPC, blaCMY, blaDHA, blaACC, blaTEM, blaSHV, blaFOX, blaGES, blaIMI, blaOKP, blaOXY, blaPER, blaVEB, blaSMP, blaGIM, blaSIM | C3: CAZ | D3: + | E3: 2 | H3: =VC!C55 -> 0 | I3: =VC!D55 -> 0 | J3: =VC!E55 -> 0 | K3: =VC!F55 -> 0 | L3: =VC!G55 -> 0 | M3: =VC!H55 -> 0 | N3: =VC!I55 -> 0 | O3: =VC!J55 -> 0 | ... HC3: =VC!GX55 -> 0
A4: ACQUIRED | B4: blaNDM, blaSMP, blaGIM, blaSIM, blaVIM, blaIMP, blaKPC, blaGES, blaIMI, blaVEB | C4: MER | D4: + | E4: 2 | H4: =VC!C56 -> 0 | I4: =VC!D56 -> 0 | J4: =VC!E56 -> 0 | K4: =VC!F56 -> 0 | L4: =VC!G56 -> 0 | M4: =VC!H56 -> 0 | N4: =VC!I56 -> 0 | O4: =VC!J56 -> 0 | ... HC4: =VC!GX56 -> 0
A5: ACQUIRED | B5: blaOXA | C5: MER | D5: + | E5: 1 | H5: =VC!C56 -> 0 | I5: =VC!D56 -> 0 | J5: =VC!E56 -> 0 | K5: =VC!F56 -> 0 | L5: =VC!G56 -> 0 | M5: =VC!H56 -> 0 | N5: =VC!I56 -> 0 | O5: =VC!J56 -> 0 | ... HC5: =VC!GX56 -> 0
A6: ACQUIRED | B6: aac(6')-Ib-cr, oqx, qepA, qnr, crpP | C6: CIP | D6: + | E6: 1 | H6: =VC!C57 -> 0 | I6: =VC!D57 -> 0 | J6: =VC!E57 -> 0 | K6: =VC!F57 -> 0 | L6: =VC!G57 -> 0 | M6: =VC!H57 -> 0 | N6: =VC!I57 -> 0 | O6: =VC!J57 -> 0 | ... HC6: =VC!GX57 -> 0
A7: ACQUIRED | B7: blaNDM, blaSMP, blaGIM, blaSIM, blaVIM, blaIMP, blaKPC, blaGES, blaIMI, blaVEB, blaOXA (espectro extendido) | C7: C/T | D7: + | E7: 2 | H7: =VC!C58 -> 0 | I7: =VC!D58 -> 0 | J7: =VC!E58 -> 0 | K7: =VC!F58 -> 0 | L7: =VC!G58 -> 0 | M7: =VC!H58 -> 0 | N7: =VC!I58 -> 0 | O7: =VC!J58 -> 0 | ... HC7: =VC!GX58 -> 0
A8: PA0004 | B8: gyrB | C8: CIP | D8: + | E8: 1 | F8: Gain of function | G8: SOLO REGION QRDR (466-468) | H8: =VC!C2 -> 0 | I8: =VC!D2 -> 0 | J8: =VC!E2 -> 0 | K8: =VC!F2 -> 0 | L8: =VC!G2 -> 0 | M8: =VC!H2 -> 0 | N8: =VC!I2 -> E468D | O8: =VC!J2 -> 0 | ... HC8: =VC!GX2 -> 0
A9: PA0424 | B9: mexR | C9: CAZ | D9: + | E9: 0,5/0,25 | F9: Loss of function | G9: DOBLE SCORE | H9: =VC!C4 -> 0 | I9: =VC!D4 -> 0 | J9: =VC!E4 -> 0 | K9: =VC!F4 -> 0 | L9: =VC!G4 -> 0 | M9: =VC!H4 -> 0 | N9: =VC!I4 -> 0 | O9: =VC!J4 -> 0 | ... HC9: =VC!GX4 -> 0
A10: PA0424 | B10: mexR | C10: MER | D10: + | E10: 0,5/0,25 | F10: Loss of function | G10: DOBLE SCORE | H10: =VC!C4 -> 0 | I10: =VC!D4 -> 0 | J10: =VC!E4 -> 0 | K10: =VC!F4 -> 0 | L10: =VC!G4 -> 0 | M10: =VC!H4 -> 0 | N10: =VC!I4 -> 0 | O10: =VC!J4 -> 0 | ... HC10: =VC!GX4 -> 0
A11: PA0424 | B11: mexR | C11: CIP | D11: + | E11: 0,5/0,25 | F11: Loss of function | G11: DOBLE SCORE | H11: =VC!C4 -> 0 | I11: =VC!D4 -> 0 | J11: =VC!E4 -> 0 | K11: =VC!F4 -> 0 | L11: =VC!G4 -> 0 | M11: =VC!H4 -> 0 | N11: =VC!I4 -> 0 | O11: =VC!J4 -> 0 | ... HC11: =VC!GX4 -> 0
A12: PA0424 | B12: mexR | C12: C/T | D12: + | E12: 0,25/0,125 | F12: Loss of function | G12: DOBLE SCORE | H12: =VC!C4 -> 0 | I12: =VC!D4 -> 0 | J12: =VC!E4 -> 0 | K12: =VC!F4 -> 0 | L12: =VC!G4 -> 0 | M12: =VC!H4 -> 0 | N12: =VC!I4 -> 0 | O12: =VC!J4 -> 0 | ... HC12: =VC!GX4 -> 0
A13: PA0425 | B13: mexA | C13: CAZ | D13: - | E13: -0.5 | F13: Loss of function | G13: SOLO STOP CODON/FS | H13: =VC!C5 -> 0 | I13: =VC!D5 -> 0 | J13: =VC!E5 -> D373N | K13: =VC!F5 -> 0 | L13: =VC!G5 -> 0 | M13: =VC!H5 -> 0 | N13: =VC!I5 -> 0 | O13: =VC!J5 -> 0 | ... HC13: =VC!GX5 -> 0
A14: PA0425 | B14: mexA | C14: MER | D14: - | E14: -0.5 | F14: Loss of function | G14: SOLO STOP CODON/FS | H14: =VC!C5 -> 0 | I14: =VC!D5 -> 0 | J14: =VC!E5 -> D373N | K14: =VC!F5 -> 0 | L14: =VC!G5 -> 0 | M14: =VC!H5 -> 0 | N14: =VC!I5 -> 0 | O14: =VC!J5 -> 0 | ... HC14: =VC!GX5 -> 0
A15: PA0425 | B15: mexA | C15: CIP | D15: - | E15: -0.5 | F15: Loss of function | G15: SOLO STOP CODON/FS | H15: =VC!C5 -> 0 | I15: =VC!D5 -> 0 | J15: =VC!E5 -> D373N | K15: =VC!F5 -> 0 | L15: =VC!G5 -> 0 | M15: =VC!H5 -> 0 | N15: =VC!I5 -> 0 | O15: =VC!J5 -> 0 | ... HC15: =VC!GX5 -> 0
A16: PA0425 | B16: mexA | C16: C/T | D16: - | E16: -0.25 | F16: Loss of function | G16: SOLO STOP CODON/FS | H16: =VC!C5 -> 0 | I16: =VC!D5 -> 0 | J16: =VC!E5 -> D373N | K16: =VC!F5 -> 0 | L16: =VC!G5 -> 0 | M16: =VC!H5 -> 0 | N16: =VC!I5 -> 0 | O16: =VC!J5 -> 0 | ... HC16: =VC!GX5 -> 0
A17: PA0426 | B17: mexB | C17: CAZ | D17: - | E17: -0.5 | F17: Loss of function | G17: SOLO STOP CODON/FS | H17: =VC!C6 -> 0 | I17: =VC!D6 -> 0 | J17: =VC!E6 -> 0 | K17: =VC!F6 -> 0 | L17: =VC!G6 -> 0 | M17: =VC!H6 -> 0 | N17: =VC!I6 -> G957D | O17: =VC!J6 -> 0 | ... HC17: =VC!GX6 -> 0
A18: PA0426 | B18: mexB | C18: MER | D18: - | E18: -0.5 | F18: Loss of function | G18: SOLO STOP CODON/FS | H18: =VC!C6 -> 0 | I18: =VC!D6 -> 0 | J18: =VC!E6 -> 0 | K18: =VC!F6 -> 0 | L18: =VC!G6 -> 0 | M18: =VC!H6 -> 0 | N18: =VC!I6 -> G957D | O18: =VC!J6 -> 0 | ... HC18: =VC!GX6 -> 0
A19: PA0426 | B19: mexB | C19: CIP | D19: - | E19: -0.5 | F19: Loss of function | G19: SOLO STOP CODON/FS | H19: =VC!C6 -> 0 | I19: =VC!D6 -> 0 | J19: =VC!E6 -> 0 | K19: =VC!F6 -> 0 | L19: =VC!G6 -> 0 | M19: =VC!H6 -> 0 | N19: =VC!I6 -> G957D | O19: =VC!J6 -> 0 | ... HC19: =VC!GX6 -> 0
A20: PA0426 | B20: mexB | C20: C/T | D20: - | E20: -0.25 | F20: Loss of function | G20: SOLO STOP CODON/FS | H20: =VC!C6 -> 0 | I20: =VC!D6 -> 0 | J20: =VC!E6 -> 0 | K20: =VC!F6 -> 0 | L20: =VC!G6 -> 0 | M20: =VC!H6 -> 0 | N20: =VC!I6 -> G957D | O20: =VC!J6 -> 0 | ... HC20: =VC!GX6 -> 0
A21: PA0427 | B21: oprM | C21: TOB | D21: - | E21: -0.5 | F21: Loss of function | G21: SOLO STOP CODON/FS | H21: =VC!C7 -> 0 | I21: =VC!D7 -> 0 | J21: =VC!E7 -> 0 | K21: =VC!F7 -> 0 | L21: =VC!G7 -> 0 | M21: =VC!H7 -> 0 | N21: =VC!I7 -> 0 | O21: =VC!J7 -> 0 | ... HC21: =VC!GX7 -> 0
A22: PA0427 | B22: oprM | C22: CAZ | D22: - | E22: -0.5 | F22: Loss of function | G22: SOLO STOP CODON/FS | H22: =VC!C7 -> 0 | I22: =VC!D7 -> 0 | J22: =VC!E7 -> 0 | K22: =VC!F7 -> 0 | L22: =VC!G7 -> 0 | M22: =VC!H7 -> 0 | N22: =VC!I7 -> 0 | O22: =VC!J7 -> 0 | ... HC22: =VC!GX7 -> 0
A23: PA0427 | B23: oprM | C23: MER | D23: - | E23: -0.5 | F23: Loss of function | G23: SOLO STOP CODON/FS | H23: =VC!C7 -> 0 | I23: =VC!D7 -> 0 | J23: =VC!E7 -> 0 | K23: =VC!F7 -> 0 | L23: =VC!G7 -> 0 | M23: =VC!H7 -> 0 | N23: =VC!I7 -> 0 | O23: =VC!J7 -> 0 | ... HC23: =VC!GX7 -> 0
A24: PA0427 | B24: oprM | C24: CIP | D24: - | E24: -0.5 | F24: Loss of function | G24: SOLO STOP CODON/FS | H24: =VC!C7 -> 0 | I24: =VC!D7 -> 0 | J24: =VC!E7 -> 0 | K24: =VC!F7 -> 0 | L24: =VC!G7 -> 0 | M24: =VC!H7 -> 0 | N24: =VC!I7 -> 0 | O24: =VC!J7 -> 0 | ... HC24: =VC!GX7 -> 0
A25: PA0427 | B25: oprM | C25: C/T | D25: - | E25: -0.25 | F25: Loss of function | G25: SOLO STOP CODON/FS | H25: =VC!C7 -> 0 | I25: =VC!D7 -> 0 | J25: =VC!E7 -> 0 | K25: =VC!F7 -> 0 | L25: =VC!G7 -> 0 | M25: =VC!H7 -> 0 | N25: =VC!I7 -> 0 | O25: =VC!J7 -> 0 | ... HC25: =VC!GX7 -> 0
A26: PA0807 | B26: ampDh3 | C26: CAZ | D26: + | E26: 0,25/0,125 | F26: Loss of function | G26: DOBLE SCORE | H26: =VC!C8 -> 0 | I26: =VC!D8 -> 0 | J26: =VC!E8 -> 0 | K26: =VC!F8 -> 0 | L26: =VC!G8 -> 0 | M26: =VC!H8 -> 0 | N26: =VC!I8 -> 0 | O26: =VC!J8 -> 0 | ... HC26: =VC!GX8 -> 0
A27: PA0958 | B27: oprD | C27: MER | D27: + | E27: 0,5/0,25 | F27: Loss of function | G27: DOBLE SCORE | H27: =VC!C10 -> nt473∆14 | I27: =VC!D10 -> 0 | J27: =VC!E10 -> 0 | K27: =VC!F10 -> 0 | L27: =VC!G10 -> W138X | M27: =VC!H10 -> 0 | N27: =VC!I10 -> nt1056∆1 | O27: =VC!J10 -> 0 | ... HC27: =VC!GX10 -> 0
A28: PA1798 | B28: parS | C28: TOB | D28: + | E28: 0,5/0,25 | F28: Gain of function | G28: DOBLE SCORE (L14Q, V101M, L137P, A138T, A168V, Q232E, G361R) | H28: =VC!C14 -> L79P | I28: =VC!D14 -> 0 | J28: =VC!E14 -> V238L | K28: =VC!F14 -> 0 | L28: =VC!G14 -> 0 | M28: =VC!H14 -> 0 | N28: =VC!I14 -> L137P; V216A | O28: =VC!J14 -> 0 | ... HC28: =VC!GX14 -> 0
A29: PA1798 | B29: parS | C29: MER | D29: + | E29: 0,5/0,25 | F29: Gain of function | G29: DOBLE SCORE (L14Q, V101M, L137P, A138T, A168V, Q232E, G361R) | H29: =VC!C14 -> L79P | I29: =VC!D14 -> 0 | J29: =VC!E14 -> V238L | K29: =VC!F14 -> 0 | L29: =VC!G14 -> 0 | M29: =VC!H14 -> 0 | N29: =VC!I14 -> L137P; V216A | O29: =VC!J14 -> 0 | ... HC29: =VC!GX14 -> 0
A30: PA1798 | B30: parS | C30: CIP | D30: + | E30: 0,25/0,125 | F30: Gain of function | G30: DOBLE SCORE (L14Q, V101M, L137P, A138T, A168V, Q232E, G361R) | H30: =VC!C14 -> L79P | I30: =VC!D14 -> 0 | J30: =VC!E14 -> V238L | K30: =VC!F14 -> 0 | L30: =VC!G14 -> 0 | M30: =VC!H14 -> 0 | N30: =VC!I14 -> L137P; V216A | O30: =VC!J14 -> 0 | ... HC30: =VC!GX14 -> 0
A31: PA1799 | B31: parR | C31: TOB | D31: + | E31: 0,5/0,25 | F31: Gain of function | G31: DOBLE SCORE (M59I, E156K) | H31: =VC!C15 -> 0 | I31: =VC!D15 -> 0 | J31: =VC!E15 -> 0 | K31: =VC!F15 -> 0 | L31: =VC!G15 -> 0 | M31: =VC!H15 -> 0 | N31: =VC!I15 -> 0 | O31: =VC!J15 -> 0 | ... HC31: =VC!GX15 -> R178C
A32: PA1799 | B32: parR | C32: MER | D32: + | E32: 0,5/0,25 | F32: Gain of function | G32: DOBLE SCORE (M59I, E156K) | H32: =VC!C15 -> 0 | I32: =VC!D15 -> 0 | J32: =VC!E15 -> 0 | K32: =VC!F15 -> 0 | L32: =VC!G15 -> 0 | M32: =VC!H15 -> 0 | N32: =VC!I15 -> 0 | O32: =VC!J15 -> 0 | ... HC32: =VC!GX15 -> R178C
A33: PA1799 | B33: parR | C33: CIP | D33: + | E33: 0,25/0,125 | F33: Gain of function | G33: DOBLE SCORE (M59I, E156K) | H33: =VC!C15 -> 0 | I33: =VC!D15 -> 0 | J33: =VC!E15 -> 0 | K33: =VC!F15 -> 0 | L33: =VC!G15 -> 0 | M33: =VC!H15 -> 0 | N33: =VC!I15 -> 0 | O33: =VC!J15 -> 0 | ... HC33: =VC!GX15 -> R178C
A34: PA2018 | B34: mexY | C34: TOB | D34: - | E34: -0.5 | F34: Loss of function | G34: SÓLO STOP CODON/ FS | H34: =VC!C16 -> D428N | I34: =VC!D16 -> 0 | J34: =VC!E16 -> 0 | K34: =VC!F16 -> A708T | L34: =VC!G16 -> D428N | M34: =VC!H16 -> L239P | N34: =VC!I16 -> 0 | O34: =VC!J16 -> R1033L | ... HC34: =VC!GX16 -> 0
A35: PA2018 | B35: mexY | C35: MER | D35: - | E35: -0.5 | F35: Loss of function | G35: SÓLO STOP CODON/ FS | H35: =VC!C16 -> D428N | I35: =VC!D16 -> 0 | J35: =VC!E16 -> 0 | K35: =VC!F16 -> A708T | L35: =VC!G16 -> D428N | M35: =VC!H16 -> L239P | N35: =VC!I16 -> 0 | O35: =VC!J16 -> R1033L | ... HC35: =VC!GX16 -> 0
A36: PA2018 | B36: mexY | C36: CIP | D36: - | E36: -0.25 | F36: Loss of function | G36: SÓLO STOP CODON/ FS | H36: =VC!C16 -> D428N | I36: =VC!D16 -> 0 | J36: =VC!E16 -> 0 | K36: =VC!F16 -> A708T | L36: =VC!G16 -> D428N | M36: =VC!H16 -> L239P | N36: =VC!I16 -> 0 | O36: =VC!J16 -> R1033L | ... HC36: =VC!GX16 -> 0
A37: PA2019 | B37: mexX | C37: TOB | D37: - | E37: -0.5 | F37: Loss of function | G37: SÓLO STOP CODON/ FS | H37: =VC!C17 -> 0 | I37: =VC!D17 -> 0 | J37: =VC!E17 -> 0 | K37: =VC!F17 -> 0 | L37: =VC!G17 -> 0 | M37: =VC!H17 -> 0 | N37: =VC!I17 -> 0 | O37: =VC!J17 -> 0 | ... HC37: =VC!GX17 -> 0
A38: PA2019 | B38: mexX | C38: MER | D38: - | E38: -0.5 | F38: Loss of function | G38: SÓLO STOP CODON/ FS | H38: =VC!C17 -> 0 | I38: =VC!D17 -> 0 | J38: =VC!E17 -> 0 | K38: =VC!F17 -> 0 | L38: =VC!G17 -> 0 | M38: =VC!H17 -> 0 | N38: =VC!I17 -> 0 | O38: =VC!J17 -> 0 | ... HC38: =VC!GX17 -> 0
A39: PA2019 | B39: mexX | C39: CIP | D39: - | E39: -0.25 | F39: Loss of function | G39: SÓLO STOP CODON/ FS | H39: =VC!C17 -> 0 | I39: =VC!D17 -> 0 | J39: =VC!E17 -> 0 | K39: =VC!F17 -> 0 | L39: =VC!G17 -> 0 | M39: =VC!H17 -> 0 | N39: =VC!I17 -> 0 | O39: =VC!J17 -> 0 | ... HC39: =VC!GX17 -> 0
A40: PA2020 | B40: mexZ | C40: TOB | D40: + | E40: 0,5/0,25 | F40: Loss of function | G40: DOBLE SCORE | H40: =VC!C18 -> 0 | I40: =VC!D18 -> D83E | J40: =VC!E18 -> 0 | K40: =VC!F18 -> 0 | L40: =VC!G18 -> aa103∆1 | M40: =VC!H18 -> 0 | N40: =VC!I18 -> aa163InsY | O40: =VC!J18 -> 0 | ... HC40: =VC!GX18 -> 0
...

Sheet VC
A1: LOCUS | B1: GENE | C1: AND01-001 | D1: AND01-004 | E1: AND01-005 | F1: AND01-006 | G1: AND02-001 | H1: AND02-002 | I1: AND02-003 | J1: AND02-006 | K1: AND03-001 | L1: AND03-003 | M1: AND03-009 | N1: AND03-012 | O1: AND04-001 | P1: AND04-002 | Q1: AND04-003 | R1: AND04-004A | S1: AND05-004 | T1: AND05-005 | U1: AND05-008 | V1: AND05-009 | W1: AND06-001 | X1: AND06-002 | Y1: AND06-003 | Z1: AND06-006 | AA1: AND07-001 | AB1: AND07-002 | AC1: AND07-003 | AD1: AND07-005 | AE1: ARA01-001 | AF1: ARA01-002 | AG1: ARA01-003 | AH1: ARA01-006 | AI1: ARA02-001 | AJ1: ARA02-002 | AK1: ARA02-005 | AL1: ARA02-007 | AM1: ARA03-001 | AN1: ARA03-002 | AO1: ARA03-003 | AP1: ARA03-004 | AQ1: AST01-001 | AR1: AST01-003 | AS1: AST01-005 | AT1: AST01-006 | AU1: BAL01-001 | AV1: BAL01-003 | AW1: BAL01-004 | AX1: BAL01-006 | AY1: BAL02-001 | AZ1: BAL02-005 | BA1: BAL02-006 | BB1: BAL02-009 | BC1: BAL03-001 | BD1: BAL03-002 | BE1: BAL03-003 | BF1: BAL03-006 | BG1: BAL04-001 | BH1: BAL04-002 | BI1: BAL04-003 | BJ1: BAL04-004 | BK1: CAN01-001 | BL1: CAN01-002 | BM1: CAN01-003 | BN1: CAN01-004 | BO1: CAT01-001 | BP1: CAT01-004 | BQ1: CAT01-005 | BR1: CAT01-007 | BS1: CAT02-001 | BT1: CAT02-002 | BU1: CAT02-003 | BV1: CAT02-004 | BW1: CAT03-001 | BX1: CAT03-002 | BY1: CAT03-004 | BZ1: CAT03-005 | CA1: CAT04-001 | CB1: CAT04-002 | CC1: CAT04-003 | CD1: CAT04-004 | CE1: CAT05-001 | CF1: CAT05-002 | CG1: CAT05-003 | CH1: CAT05-004 | CI1: CAT06-001 | CJ1: CAT06-004 | CK1: CAT06-005 | CL1: CAT06-008 | CM1: CAT07-001 | CN1: CAT07-002 | CO1: CAT07-003 | CP1: CAT07-005 | CQ1: CAT08-013 | CR1: CAT08-014 | CS1: CAT08-015 | CT1: CAT08-016 | CU1: CAT09-001 | CV1: CAT09-002 | CW1: CAT09-003 | CX1: CAT09-004 | CY1: CLE01-003 | CZ1: CLE01-006 | DA1: CLE01-007 | DB1: CLE01-008 | DC1: CLE02-001 | DD1: CLE02-002 | DE1: CLE02-004 | DF1: CLE02-006 | DG1: CLE03-003 | DH1: CLE03-004 | DI1: CLE03-005 | DJ1: CLE03-006 | DK1: CLM01-001 | DL1: CLM01-002 | DM1: CLM01-003 | DN1: CLM01-004 | DO1: CLM02-004 | DP1: CLM02-005 | DQ1: CLM02-013 | DR1: CLM02-014 | DS1: CVA01-001 | DT1: CVA01-002 | DU1: CVA01-005 | DV1: CVA01-006 | DW1: CVA02-001 | DX1: CVA02-002 | DY1: CVA02-003 | DZ1: CVA02-005 | EA1: CVA03-001 | EB1: CVA03-002 | EC1: CVA03-004 | ED1: CVA03-006 | EE1: EXT01-001 | EF1: EXT01-003 | EG1: EXT01-004 | EH1: EXT01-005 | EI1: GAL01-001 | EJ1: GAL01-002 | EK1: GAL01-003 | EL1: GAL01-012 | EM1: GAL02-001 | EN1: GAL02-002 | EO1: GAL02-004 | EP1: GAL02-006 | EQ1: GAL03-002 | ER1: GAL03-003 | ES1: GAL03-004 | ET1: GAL03-005 | EU1: GAL04-001 | EV1: GAL04-002 | EW1: GAL04-004 | EX1: GAL04-005 | EY1: GAL05-002 | EZ1: GAL05-003 | FA1: GAL05-004 | FB1: GAL05-005 | FC1: GAL06-001 | FD1: GAL06-002 | FE1: GAL06-003 | FF1: GAL06-004 | FG1: ICA01-001 | FH1: ICA01-002 | FI1: ICA01-003 | FJ1: ICA01-004 | FK1: LRJ01-002 | FL1: LRJ01-005 | FM1: LRJ01-010 | FN1: LRJ01-012 | FO1: MAD01-001 | FP1: MAD01-002 | FQ1: MAD01-004 | FR1: MAD01-005 | FS1: MAD02-001 | FT1: MAD02-002 | FU1: MAD02-004 | FV1: MAD02-005 | FW1: MAD03-001 | FX1: MAD03-002 | FY1: MAD03-004 | FZ1: MAD03-005 | GA1: MAD04-001 | GB1: MAD04-002 | GC1: MAD04-003 | GD1: MAD04-004 | GE1: MAD05-003 | GF1: MAD05-008 | GG1: MAD05-009 | GH1: MAD05-011 | GI1: MAD06-001 | GJ1: MAD06-002 | GK1: MAD06-004 | GL1: MAD06-005 | GM1: MUR01-001 | GN1: MUR01-002 | GO1: MUR01-003 | GP1: MUR01-004 | GQ1: NAV01-001 | GR1: NAV01-004 | GS1: NAV01-005 | GT1: NAV01-012 | GU1: PVA01-003 | GV1: PVA01-006 | GW1: PVA01-007 | GX1: PVA01-011
A2: PA0004 | B2: gyrB | I2: E468D | AF2: S466F | BE2: S466Y | CN2: E468D | DM2: S466Y | DP2: E468D | DR2: E468D | DY2: S466F | EG2: S466Y | EW2: S466F | EZ2: E468D | FP2: E468D | FW2: E468D | GG2: S466F
A3: PA0005 | B3: lptA | ER3: R66H
A4: PA0424 | B4: mexR | W4: S92N | X4: aa11∆4 | AF4: L102P | AJ4: nt402∆11 | AW4: L95F | BI4: nt81InsT | BV4: nt266InsG | CA4: R73L | CN4: L95F | CR4: nt161InsC | DA4: R82H | EF4: nt217∆1 | ER4: N79S | FM4: Q49X | FR4: aa90∆4 | GW4: nt492InsACCC
A5: PA0425 | B5: mexA | E5: D373N | AS5: I63V | BA5: D373N | BH5: K86E | BO5: D373N | CB5: D373N | CD5: D373N | CI5: Q143P | CJ5: N269S | CS5: A33T | DF5: K86E | DL5: K76Q | DP5: Q104X | DY5: E53X | EA5: A111T | EB5: A117V | EM5: R326Q | EQ5: K86E | GP5: N269S
A6: PA0426 | B6: mexB | I6: G957D | V6: G957D | AH6: G957D; V1042A | BB6: G957D | BJ6: E422X | BL6: Q319X | CF6: nt1135∆1 | CL6: A735D | CU6: G957D | DE6: G957D | DV6: nt881InsGG | DW6: G957D | EA6: G957D | EB6: nt2936∆1 | EO6: nt3018∆5 | ER6: A707S; I963V | ET6: T98A | EV6: G957D | EW6: G860D | EY6: G957D | EZ6: G957D | FG6: G957D | FI6: G957D | GL6: A539T | GN6: G957D | GS6: P190L
A7: PA0427 | B7: oprM | BI7: nt1451InsC | CK7: T198P | CQ7: T180I | DM7: nt501∆5 | ER7: Q265E
A8: PA0807 | B8: ampDh3 | N8: I67T | P8: R66C | AB8: I67T | AE8: A51T | BB8: P55S | BE8: R66C | BS8: I67T | CB8: I67T | CD8: I67T | DP8: nt410∆1 | DR8: nt410∆1 | DT8: I67T | ED8: Y207X | EZ8: L246P | FK8: I67T | FM8: A51T | FO8: I67T | GB8: I67T
A9: PA0869 | B9: PBP7 | E9: V61A | H9: V171I | M9: G137D | AS9: T200I | BI9: V305M | BL9: R112G | CS9: T200I; A290T | CW9: R175P | ER9: G30R | FF9: P88S | GN9: V9A | GQ9: H205N | GS9: V171I
A10: PA0958a | B10: oprD | C10: nt473∆14 | G10: W138X | I10: nt1056∆1 | V10: F321V, N430Y | Z10: nt1185∆1 | AG10: nt1206InsC | AH10: aa397∆9 | AN10: nt1206InsC | AO10: nt209∆10 | AQ10: D43N | AV10: Q142X | AW10: nt1206InsC | AX10: Q142X | BI10: nt438InsC | BJ10: W339X | BL10: nt175∆11 | BM10: L432P | BN10: nt199∆1 | BY10: Q142X | CA10: nt1206InsC | CE10: Q142X | CF10: Q142X | CH10: W277X | CK10: Q142X | CL10: Q142X | DE10: nt350InsC | DP10: W415X | DR10: W415X | DS10: T103S, K115T, F170L, nt169∆1, nt175InsA | DV10: nt55InsGCACT | DW10: D43N, M135I, E185Q, P186G, V189T, S267A, T276A, G310E, A315G, L347M, L359V, Q422E | DZ10: nt55InsGCACT | EC10: nt1206InsC | EE10: Y225X | EO10: L407P | EP10: S408P | EV10: W417X | EZ10: Q158X | FF10: Q422X | FI10: M135I | FJ10: D43N | FV10: W277X | GG10: W339G | GL10: D43N | GS10: nt742∆1 | GT10: nt991InsAC | GW10: Q142X
A11: PA1179 | B11: phoP | BK11: E35G | EN11: G70D
A12: PA1180 | B12: phoQ | AY12: R240C | BK12: S300R | BX12: S300R | CN12: A23V | CP12: Q308R | CT12: S300R | DY12: D326N | EH12: S300R | EJ12: S157T | ER12: D90E; E267Q; V369L | EW12: S300R | EX12: R3C
A13: PA1777 | B13: oprF | DB13: D64Y | DM13: nt164∆1
A14: PA1798 | B14: parS | C14: L79P | E14: V238L | I14: L137P; V216A | M14: S352I | U14: A82T | Z14: A345T | AJ14: R83K; V216A | AO14: A82T | AT14: R356L | BE14: R385H | BK14: aa118∆4 | BM14: L137P; nt998∆1 | BP14: A82T | BS14: G303R | BT14: R356L | CM14: S352I | CR14: A82T | CV14: R356L | DS14: V238L | DT14: Y73C | DY14: S33R | ED14: A293V | EI14: R356L | EL14: R356L | EM14: A82T; L346P | EP14: R356L | EZ14: V216A | FD14: S277N | FG14: R7H | FS14: D348N | FX14: Q349K | FZ14: V238L | GC14: D351N | GE14: A395T | GF14: V152A | GK14: A82T | GP14: A29V | GT14: L137P
A15: PA1799 | B15: parR | BO15: L90I | DJ15: aa214∆1 | FN15: P128S | GI15: V55I; I80L | GX15: R178C
A16: PA2018 | B16: mexY | C16: D428N | F16: A708T | G16: D428N | H16: L239P | J16: R1033L | K16: T742I | O16: A131T; P1032S | U16: V875M; N1036S | Z16: N709S | AC16: A586T; N709H | AH16: R706H | AS16: A772T | BB16: R251H; I543V | BH16: P1032S | BL16: G530S | BM16: G530S | CY16: A285T | DF16: P1032S | DI16: DELETED | DM16: R1033L | DN16: D628H | DU16: R1024S | DW16: R706H | DY16: T472P; P1032S | ED16: E505G | EG16: D724V | EQ16: P1032S | ER16: S48N; T472A; D502G; R519H; Q843R; I849V; A865D | FF16: A772T | FI16: R706H | FJ16: D428N | FN16: I531T | FR16: A772T | GF16: T238I | GI16: G1002A | GL16: T393A | GO16: A527V; V548M | GT16: G530S | GV16: G530S
A17: PA2019 | B17: mexX | K17: S320P | M17: I212L | P17: H119Y | U17: D346H | W17: S382G | AC17: S382G | AO17: D346H | BB17: A38T | BC17: S382G | BE17: H119Y | BI17: A375P; A383P | BP17: D346H | CJ17: V376M | CR17: D346H | DI17: DELETED | DU17: L154Q | ED17: R151H | EL17: Y255X | EM17: D346H | ER17: A15T; A48V; E142K; D384G | ES17: A36T | FN17: Q4H | FX17: W358C | FY17: Q396X | GG17: W358C | GK17: D346H | GL17: H119Y | GO17: A36T | GP17: R69Q
A18: PA2020 | B18: mexZ | D18: D83E | G18: aa103∆1 | I18: aa163InsY | X18: T12N | AG18: W185X | AL18: nt484InsC | AV18: G195D | AX18: G195D | AZ18: aa187∆6 | BB18: G68D | BD18: G195D | BL18: Q140K | BN18: G195D | BO18: nt526∆8 | BR18: V105G | BY18: G195D | CE18: G195D | CF18: G195D | CH18: V105G | CK18: G195D | CL18: G195D | CU18: aa48∆9 | CW18: H51D | DB18: A35V | DG18: R45C | DH18: nt386∆1 | DI18: DELETED | DL18: D83E | DP18: G195D | DR18: G195D | DV18: G195D | DX18: L37P | DY18: nt491∆10 | DZ18: G195D | EB18: Q132X | EC18: nt320∆16 | EN18: Y204X | ER18: F192L | EU18: nt367∆10 | EV18: nt100∆1 | EZ18: aa163InsY | FD18: A47V | FL18: G195D | FN18: A81V; Q134R | FP18: Q132P | FV18: G195D | GG18: A88P | GH18: G195D | GI18: nt227∆1 | GS18: R104W | GW18: G195D
A19: PA2023 | B19: galU | CF19: nt61∆5 | DD19: Δ63 | DI19: DELETED | DX19: G175S | EA19: aa207∆4 | EB19: Y12C; L21R; G56S | EN19: C242X | FE19: nt679∆1 | GS19: F248S
A20: PA2272 | B20: PBP3a | H20: D185E | M20: V187G; K358Q | N20: I143L | AB20: I143L | AQ20: E66G | AS20: P54S | AV20: E37K | AX20: E37K | BD20: E37K | BH20: H99R; L552V | BK20: A20S | BN20: E37K | BS20: I143L | BX20: A20S | BY20: E37K | CE20: E37K | CF20: E37K | CK20: E37K | CL20: E37K | DC20: K358Q | DL20: T335S | DP20: E37K | DR20: E37K | DV20: E37K | DX20: I451T | DZ20: E37K | EF20: K358Q | EG20: V18I; E90Q; A371T | EH20: A20S | ER20: V18I; A85T; A86G; N164D; V187I | EW20: A20S | FC20: V18I | FL20: E37K | FV20: E37K | GB20: I143L | GC20: K358Q | GE20: A86V | GH20: E37K | GW20: E37K
A21: PA2491 | B21: mexS | Q21: L32Q; V333M | AC21: P90L | AR21: Q100H | AZ21: G231S | BB21: V104A | BL21: ∆720 | BX21: K43E | CB21: V77I | CD21: V77I | CJ21: M106T | CP21: G11S | CU21: A52V | CV21: F10L | DK21: P13L | DQ21: nt907∆14 | DU21: P24L | EC21: V241M | EE21: nt396InsGT | EF21: X340ext | EG21: A175V; E181D; S289T; V308I | EL21: N246K | EN21: G76S | EO21: P225L | EP21: N246K | EQ21: DELETED | ER21: A175V; E181D; E286D | EW21: G248C | FC21: A175V; E181D; S289T; V308I | FK21: nt350∆1 | GI21: E205V | GQ21: G78S; aa147InsLKAG | GV21: D232G | GX21: S84F
A22: PA2492 | B22: mexT | C22: nt234∆8 | D22: nt234∆8 | E22: nt234∆8 | F22: nt234∆8 | G22: nt234∆8 | H22: nt234∆8 | I22: nt234∆8 | J22: nt234∆8 | K22: nt234∆8 | L22: nt234∆8 | M22: nt234∆8 | N22: nt234∆8 | O22: nt234∆8 | P22: nt234∆8 | Q22: R334C; nt234∆8 | R22: nt234∆8 | S22: nt234∆8 | T22: nt234∆8 | U22: nt234∆8 | V22: nt234∆8 | W22: nt234∆8 | X22: nt234∆8 | Y22: nt234∆8 | Z22: nt234∆8 | AB22: nt234∆8 | AC22: nt234∆8 | AD22: nt234∆8 | AE22: nt234∆8 | AF22: nt234∆8 | AG22: nt234∆8 | AH22: nt234∆8 | AI22: nt234∆8 | AJ22: nt234∆8 | AK22: nt234∆8 | AL22: nt234∆8 | AM22: nt234∆8 | AN22: nt234∆8 | AO22: nt234∆8 | AP22: nt234∆8 | AQ22: nt234∆8 | AR22: nt234∆8 | AS22: nt234∆8 | AT22: nt234∆8 | AU22: nt234∆8 | AV22: nt234∆8 | AW22: nt234∆8 | AX22: nt234∆8 | AY22: nt234∆8 | AZ22: nt234∆8 | BA22: nt234∆8 | BB22: nt234∆8 | BC22: nt234∆8 | BD22: nt234∆8 | BE22: nt234∆8 | BF22: nt234∆8 | BG22: nt234∆8 | BH22: nt234∆8 | BI22: nt234∆8 | BJ22: nt234∆8 | BK22: nt234∆8 | BL22: G276D; nt234∆8 | BM22: nt234∆8 | BN22: nt234∆8 | BO22: nt234∆8 | BP22: nt234∆8 | BQ22: nt234∆8 | BR22: nt234∆8 | BS22: nt234∆8 | BT22: nt234∆8 | BU22: nt234∆8 | BV22: nt234∆8 | BW22: nt234∆8 | BX22: nt234∆8 | BY22: nt234∆8 | BZ22: nt234∆8 | CA22: nt234∆8 | CB22: nt234∆8 | CC22: nt234∆8 | CD22: nt234∆8 | CE22: nt234∆8 | CF22: nt234∆8 | CG22: nt234∆8 | CH22: nt234∆8 | CI22: nt234∆8 | CJ22: nt234∆8 | CK22: nt234∆8 | CL22: nt234∆8 | CM22: nt234∆8 | CN22: V265A; nt234∆8 | CO22: nt234∆8 | CP22: A245V; nt234∆8 | CQ22: nt234∆8 | CR22: nt234∆8 | CS22: nt234∆8 | CT22: nt234∆8 | CU22: nt234∆8; nt395InsC | CV22: nt234∆8 | CW22: nt234∆8 | CX22: nt234∆8 | CY22: nt234∆8 | CZ22: nt234∆8 | DA22: nt234∆8 | DB22: nt234∆8 | DC22: nt234∆8 | DD22: nt234∆8 | DE22: nt234∆8 | DF22: nt234∆8 | DG22: nt234∆8 | DH22: nt234∆8 | DI22: nt234∆8 | DJ22: nt234∆8 | DK22: nt234∆8 | DL22: nt234∆8 | DM22: nt234∆8 | DN22: nt234∆8 | DO22: nt234∆8 | DP22: nt234∆8 | DQ22: nt234∆8 | DR22: nt234∆8 | DS22: nt234∆8 | DT22: nt234∆8 | DU22: nt234∆8 | DV22: nt234∆8 | DW22: nt234∆8 | DX22: nt234∆8 | DY22: nt234∆8 | DZ22: nt234∆8 | EA22: nt234∆8 | EB22: nt234∆8 | EC22: D96A; nt234∆8 | ED22: nt234∆8 | EE22: A47V; nt234∆8 | EF22: R334P; nt234∆8 | EG22: nt234∆8 | EH22: nt234∆8 | EI22: nt234∆8 | EJ22: nt234∆8 | EK22: nt234∆8 | EL22: nt234∆8 | EM22: nt234∆8 | EN22: nt234∆8 | EO22: nt234∆8 | EP22: nt234∆8 | EQ22: DELETED | ER22: nt234∆8 | ES22: nt234∆8 | ET22: nt234∆8 | EU22: nt234∆8 | EV22: nt234∆8 | EW22: nt234∆8 | EX22: nt234∆8 | EY22: nt234∆8 | EZ22: nt234∆8 | FA22: nt234∆8 | FB22: nt234∆8 | FC22: nt234∆8 | FD22: nt234∆8 | FE22: nt234∆8 | FF22: nt234∆8 | FG22: nt234∆8 | FH22: nt234∆8 | FI22: nt234∆8 | FJ22: nt234∆8 | FK22: nt234∆8 | FL22: nt234∆8 | FM22: nt234∆8 | FN22: nt234∆8 | FO22: nt234∆8 | FP22: nt234∆8 | FQ22: nt234∆8 | FR22: nt234∆8 | FS22: nt234∆8 | FT22: nt234∆8 | FU22: nt234∆8 | FV22: nt234∆8 | FW22: R209S; nt234∆8 | FX22: nt234∆8 | FY22: nt234∆8 | FZ22: nt234∆8 | GA22: nt234∆8 | GB22: nt234∆8 | GC22: nt234∆8 | GD22: nt234∆8 | GE22: nt234∆8 | GF22: nt234∆8 | GG22: nt234∆8 | GH22: nt234∆8 | GI22: nt234∆8 | GJ22: nt234∆8 | GK22: nt234∆8 | GL22: nt234∆8 | GM22: nt234∆8 | GN22: nt234∆8 | GO22: nt234∆8 | GP22: nt234∆8 | GQ22: nt234∆8 | GR22: nt234∆8 | GS22: nt234∆8 | GT22: nt234∆8 | GU22: nt234∆8 | GV22: nt234∆8 | GW22: nt234∆8 | GX22: nt234∆8
A23: PA2493 | B23: mexE | F23: G282S | T23: V156A | W23: P337A | BC23: P337A | BS23: G250D | CJ23: A377V | CN23: F284L | CU23: E2V; Q368R | DE23: E2V; Q368R | EQ23: DELETED | EV23: E2V; Q368R | EY23: E2V; Q368R | FJ23: V156A
A24: PA2494 | B24: mexF | AE24: F509V | AG24: Q363R | AS24: G1056D | BG24: A1062T | DC24: S510L | DT24: F509V | DX24: I753V | DY24: A598S | EB24: T95I | EC24: A550V | EQ24: DELETED | ER24: A256T; N276S; T713A | FM24: F509V | FR24: A842T | GA24: D669G | GD24: D669G | GI24: F509V
A25: PA2495 | B25: oprN | D25: A12T | L25: A228V | AC25: R363H | AK25: R151L | AS25: D102N | BA25: R455H | BC25: G364S | CJ25: T27A | CM25: P35L | DC25: A12T | DK25: R151L | DN25: A113S | DP25: P470S | DT25: R150H | ED25: T34S | EF25: A12T | EJ25: A140T | EQ25: DELETED | ER25: S77T; T275S | FZ25: V172I | GC25: D31V | GM25: A113S | GR25: D98E
A26: PA3047 | B26: PBP4 | C26: T428P | AJ26: Y61H | BQ26: G263S | BS26: D176N | BV26: A340G | CL26: A434T | EC26: T27S; S150G | ER26: R475Q | FD26: F324I | GN26: V289I | GT26: nt675InsTGGCC
A27: PA3168 | B27: gyrA | C27: T83I | G27: T83I | I27: T83I | Q27: T83I | X27: D87N | AP27: D87N | AV27: T83I; D87N | AX27: T83I; D87N | BD27: T83I; D87N | BF27: D87G | BI27: T83I | BM27: T83I | BN27: T83I; D87N | BO27: T83I | BR27: T83I; D87N | BY27: T83I; D87N | CA27: T83I; | CE27: T83I; D87N | CF27: T83I; D87N | CH27: T83I | CK27: T83I; D87N | CL27: T83I; D87N | CR27: T83I | CU27: T83I | DE27: T83I | DF27: T83I | DG27: T83I | DJ27: D87N | DK27: T83I | DP27: T83I | DQ27: T83I | DR27: T83I | DT27: D87N | DV27: T83I; D87N | DZ27: T83I; D87N | EB27: T83A; D87N | EC27: T83I | EE27: T83I | EF27: T83I | EI27: T83I | EL27: T83I | EP27: T83I | EQ27: D87N | EV27: T83I | EX27: T83I | EZ27: T83I | FD27: T83I; D87N | FG27: T83I | FL27: T83I; D87N | FR27: T83I | FV27: T83I; D87N | FW27: T83I | FX27: D87N | GH27: T83I; D87N | GT27: T83I | GV27: T83I | GW27: T83I; D87N
A28: PA3574 | B28: nalD | Q28: Q97X | BE28: aa25∆1 | BO28: T11N | BR28: ∆204 | CS28: T188A | CU28: nt263∆17 | DF28: nt396∆2 | DK28: C149Y | EC28: G78R; nt232∆19 | EL28: nt232∆19 | EP28: nt232∆19 | ER28: E21D | EV28: nt295∆17 | EX28: T188A | FD28: ∆605 | FW28: nt475∆16 | GA28: T188A | GD28: T188A | GJ28: T188A | GQ28: G172D
A29: PA3721 | B29: nalC | D29: T50P | H29: E153Q | M29: G213D | Y29: E153Q | CU29: E153Q | DD29: R191L | DE29: E153Q; nt12InsG | DJ29: E153Q | DW29: nt15∆1 | ER29: A4V | EV29: E153Q | EX29: nt15∆1 | EY29: E153Q | GO29: T100S | GS29: E153Q
A30: PA3999 | B30: PBP5 | AP30: V29I | AU30: V29I | CN30: V29I | DG30: V29I | EB30: nt390InsGT | ER30: N86S; S355T | FA30: V29I | FS30: V29I | FT30: N54S
A31: PA4003 | B31: PBP2 | AF31: A481T | BO31: A619E | BR31: A481T | CA31: A481T | CG31: D485N | CH31: A481T | EB31: D507G | ER31: A532V | ET31: L33P | GN31: S376N
A32: PA4020 | B32: mpl | E32: A356V | J32: D411A | P32: V358I | AC32: S306N | AJ32: A222G | AO32: Y35S | AP32: X452ext | AR32: D411A | AU32: X452ext | BE32: V358I | BH32: V358I | BM32: D411A; aa436InsGGF | CA32: V420M | CN32: A331T; X452ext | CP32: C410T | DC32: G231E | DG32: P178L; X452ext | DM32: D411A | DN32: C410T | DX32: T115A; nt111InsC | EE32: aa35∆4 | EF32: G231E | EG32: V124I; P274L | EI32: nt111InsC | EO32: H190Y | EP32: nt111InsC | ER32: I266S; Q347R | FA32: X452ext | FB32: D411A | FD32: S131N; A428T | FG32: R103P | FL32: V281F | FR32: D411A | FW32: nt111∆1 | GC32: D411A | GT32: D411A
A33: PA4109 | B33: ampR | AH33: A175V | AV33: G154R | AX33: G154R | BB33: A16V | BD33: G154R | BH33: G295R | BI33: D135G | BS33: S179N | BY33: G154R | CE33: G154R | CF33: G154R | CJ33: L177V | CK33: G154R | CL33: G154R | DE33: D135N | DM33: D135N | DT33: aa18InsVA | DW33: A175V | DX33: G295R | ED33: G231S | FI33: A175V | FJ33: E162Q | GQ33: G273E | GW33: G154R
A34: PA4110 | B34: ampC | AT34: G391P | BD34: E247G | BI34: R235H | BT34: G391P | CV34: G391P | DB34: G391P | EG34: Q311L | EL34: G391P | EX34: P82L
A35: PA4266 | B35: fusA1 | DM35: Q678L | DQ35: Q678R | DY35: R680C | ED35: S695T | EO35: T671A | GE35: K212T | GS35: Y552C
A36: PA4418 | B36: PBP3 | AW36: D440E | BI36: R551L | BK36: L21P | BO36: L23V | BQ36: L3V | EG36: L219V | ER36: L240V; A572V | FS36: G243S | FW36: I347T | GM36: L23V; Y146F
A37: PA4522 | B37: ampD | G37: L135Q | H37: P126Q | I37: A96T | P37: A134V | Q37: R140W | W37: A29T | AJ37: A136V | AP37: Q131X | AU37: A136V | BB37: T47I | BC37: A29T | BE37: A134V | BN37: T139M | BO37: D28G | CA37: S75F | CJ37: A144V | CN37: A136V | CO37: V10I | CY37: T182I | CZ37: A136V | DF37: A134P | DG37: A136V | DJ37: D59E | DP37: F113L | DR37: F113L | DZ37: V10G | EC37: L40Q | EG37: D83G | ER37: R11H; A85S; S175P | EZ37: A96T | FA37: A136V | FD37: A29V; W97C | FF37: G137E | FS37: A136V | GI37: G46S | GJ37: A29V; W97C | GO37: R178C | GS37: P126Q
A38: PA4597 | B38: oprJ | O38: I261T | T38: A152V | CG38: A40G | CQ38: D256G | DN38: N73D | DS38: V472A | DX38: R210H | EG38: N121S | EN38: D303V | ER38: A41T | ES38: L81I; A152T | FN38: A364V | GL38: S127N
A39: PA4598 | B39: mexD | C39: A566T; V607A | G39: A566T; V607A | H39: R596S; L1027V | W39: N775K | AL39: T778A; P829H | BC39: N775K | BI39: E602K | BK39: A566T; V607A | BX39: A566T; V607A | CG39: S606L | CT39: A566T; V607A | CY39: T489I | DB39: A734V | DT39: R333C | DU39: A905T | ED39: V364L; I610V | EG39: V364L; I610V; E650Q; H953N; A1039V | EH39: A566T; V607A | EJ39: aa1027InsLLS | EN39: aa1027InsLLS | ER39: G147D; A642D; H651R; T659S; S738N | ES39: G686R | EW39: A566T; V607A | EX39: V351L | FC39: V364L; I610V; E650Q; H953N; A1039V | FD39: T286M | FO39: I427V; G1042R | FX39: V914I | GL39: R696C | GS39: L1027V | GU39: R254H
A40: PA4599 | B40: mexC | E40: V131M | H40: V367A | Y40: A31V | AE40: G8R | AV40: E26A | AX40: E26A | BD40: E26A | BF40: nt205∆2 | BN40: E26A | BY40: E26A | CE40: E26A | CF40: E26A | CK40: E26A | CL40: E26A | CM40: M34I | CU40: A31V | DE40: A31V | DN40: T145I | DP40: E26A | DR40: E26A | DT40: Q206X | DV40: E26A | DX40: G254S | DZ40: E26A | EB40: Q134X | ER40: E152Q; V282I; N299S; G334A; V337A; E350K | EV40: A31V | EY40: A31V | FL40: E26A | FM40: G8R | FV40: E26A | FY40: E26A | GE40: S51R | GH40: E26A | GS40: V367A | GU40: V367A | GX40: E26A
...

Sheet SCORES
A1: LOCUS | B1: GENE | C1: ANTIBIOTIC | D1: EFFECT | E1: VALUE | F1: TYPE OF MUTATION | G1: OBSERVACIONES | H1: AND01-001 | I1: AND01-004 | J1: AND01-005 | K1: AND01-006 | L1: AND02-001 | M1: AND02-002 | N1: AND02-003 | O1: AND02-006 | P1: AND03-001 | Q1: AND03-003 | R1: AND03-009 | S1: AND03-012 | T1: AND04-001 | U1: AND04-002 | V1: AND04-003 | W1: AND04-004A | X1: AND05-004 | Y1: AND05-005 | Z1: AND05-008 | AA1: AND05-009 | AB1: AND06-001 | AC1: AND06-002 | AD1: AND06-003 | AE1: AND06-006 | AF1: AND07-001 | AG1: AND07-002 | AH1: AND07-003 | AI1: AND07-005 | AJ1: ARA01-001 | AK1: ARA01-002 | AL1: ARA01-003 | AM1: ARA01-006 | AN1: ARA02-001 | AO1: ARA02-002 | AP1: ARA02-005 | AQ1: ARA02-007 | AR1: ARA03-001 | AS1: ARA03-002 | AT1: ARA03-003 | AU1: ARA03-004 | AV1: AST01-001 | AW1: AST01-003 | AX1: AST01-005 | AY1: AST01-006 | AZ1: BAL01-001 | BA1: BAL01-003 | BB1: BAL01-004 | BC1: BAL01-006 | BD1: BAL02-001 | BE1: BAL02-005 | BF1: BAL02-006 | BG1: BAL02-009 | BH1: BAL03-001 | BI1: BAL03-002 | BJ1: BAL03-003 | BK1: BAL03-006 | BL1: BAL04-001 | BM1: BAL04-002 | BN1: BAL04-003 | BO1: BAL04-004 | BP1: CAN01-001 | BQ1: CAN01-002 | BR1: CAN01-003 | BS1: CAN01-004 | BT1: CAT01-001 | BU1: CAT01-004 | BV1: CAT01-005 | BW1: CAT01-007 | BX1: CAT02-001 | BY1: CAT02-002 | BZ1: CAT02-003 | CA1: CAT02-004 | CB1: CAT03-001 | CC1: CAT03-002 | CD1: CAT03-004 | CE1: CAT03-005 | CF1: CAT04-001 | CG1: CAT04-002 | CH1: CAT04-003 | CI1: CAT04-004 | CJ1: CAT05-001 | CK1: CAT05-002 | CL1: CAT05-003 | CM1: CAT05-004 | CN1: CAT06-001 | CO1: CAT06-004 | CP1: CAT06-005 | CQ1: CAT06-008 | CR1: CAT07-001 | CS1: CAT07-002 | CT1: CAT07-003 | CU1: CAT07-005 | CV1: CAT08-013 | CW1: CAT08-014 | CX1: CAT08-015 | CY1: CAT08-016 | CZ1: CAT09-001 | DA1: CAT09-002 | DB1: CAT09-003 | DC1: CAT09-004 | DD1: CLE01-003 | DE1: CLE01-006 | DF1: CLE01-007 | DG1: CLE01-008 | DH1: CLE02-001 | DI1: CLE02-002 | DJ1: CLE02-004 | DK1: CLE02-006 | DL1: CLE03-003 | DM1: CLE03-004 | DN1: CLE03-005 | DO1: CLE03-006 | DP1: CLM01-001 | DQ1: CLM01-002 | DR1: CLM01-003 | DS1: CLM01-004 | DT1: CLM02-004 | DU1: CLM02-005 | DV1: CLM02-013 | DW1: CLM02-014 | DX1: CVA01-001 | DY1: CVA01-002 | DZ1: CVA01-005 | EA1: CVA01-006 | EB1: CVA02-001 | EC1: CVA02-002 | ED1: CVA02-003 | EE1: CVA02-005 | EF1: CVA03-001 | EG1: CVA03-002 | EH1: CVA03-004 | EI1: CVA03-006 | EJ1: EXT01-001 | EK1: EXT01-003 | EL1: EXT01-004 | EM1: EXT01-005 | EN1: GAL01-001 | EO1: GAL01-002 | EP1: GAL01-003 | EQ1: GAL01-012 | ER1: GAL02-001 | ES1: GAL02-002 | ET1: GAL02-004 | EU1: GAL02-006 | EV1: GAL03-002 | EW1: GAL03-003 | EX1: GAL03-004 | EY1: GAL03-005 | EZ1: GAL04-001 | FA1: GAL04-002 | FB1: GAL04-004 | FC1: GAL04-005 | FD1: GAL05-002 | FE1: GAL05-003 | FF1: GAL05-004 | FG1: GAL05-005 | FH1: GAL06-001 | FI1: GAL06-002 | FJ1: GAL06-003 | FK1: GAL06-004 | FL1: ICA01-001 | FM1: ICA01-002 | FN1: ICA01-003 | FO1: ICA01-004 | FP1: LRJ01-002 | FQ1: LRJ01-005 | FR1: LRJ01-010 | FS1: LRJ01-012 | FT1: MAD01-001 | FU1: MAD01-002 | FV1: MAD01-004 | FW1: MAD01-005 | FX1: MAD02-001 | FY1: MAD02-002 | FZ1: MAD02-004 | GA1: MAD02-005 | GB1: MAD03-001 | GC1: MAD03-002 | GD1: MAD03-004 | GE1: MAD03-005 | GF1: MAD04-001 | GG1: MAD04-002 | GH1: MAD04-003 | GI1: MAD04-004 | GJ1: MAD05-003 | GK1: MAD05-008 | GL1: MAD05-009 | GM1: MAD05-011 | GN1: MAD06-001 | GO1: MAD06-002 | GP1: MAD06-004 | GQ1: MAD06-005 | GR1: MUR01-001 | GS1: MUR01-002 | GT1: MUR01-003 | GU1: MUR01-004 | GV1: NAV01-001 | GW1: NAV01-004 | GX1: NAV01-005 | GY1: NAV01-012 | GZ1: PVA01-003 | HA1: PVA01-006 | HB1: PVA01-007 | HC1: PVA01-011
A2: ACQUIRED | B2: aac, aad, ant | C2: TOB | D2: + | E2: 1 | H2: =VC!C54 -> aac(6')-Ic | I2: =VC!D54 -> 0 | J2: =VC!E54 -> 0 | K2: =VC!F54 -> 0 | L2: =VC!G54 -> 0 | M2: =VC!H54 -> 0 | N2: =VC!I54 -> aac(3)-Ib | O2: =VC!J54 -> 0 | ... HC2: =VC!GX54 -> 0
A3: ACQUIRED | B3: blaOXA, blaNDM, blaVIM, blaIMP, blaCTX-M, blaKPC, blaCMY, blaDHA, blaACC, blaTEM, blaSHV, blaFOX, blaGES, blaIMI, blaOKP, blaOXY, blaPER, blaVEB, blaSMP, blaGIM, blaSIM | C3: CAZ | D3: + | E3: 2/0,5 | H3: =VC!C55 -> 0 | I3: =VC!D55 -> 0 | J3: =VC!E55 -> 0 | K3: =VC!F55 -> 0 | L3: =VC!G55 -> 0 | M3: =VC!H55 -> 0 | N3: =VC!I55 -> 0 | O3: =VC!J55 -> 0 | ... HC3: =VC!GX55 -> 0
A4: ACQUIRED | B4: blaNDM, blaSMP, blaGIM, blaSIM, blaVIM, blaIMP, blaKPC, blaGES, blaIMI, blaVEB | C4: MER | D4: + | E4: 2 | H4: =VC!C56 -> 0 | I4: =VC!D56 -> 0 | J4: =VC!E56 -> 0 | K4: =VC!F56 -> 0 | L4: =VC!G56 -> 0 | M4: =VC!H56 -> 0 | N4: =VC!I56 -> 0 | O4: =VC!J56 -> 0 | ... HC4: =VC!GX56 -> 0
A5: ACQUIRED | B5: blaOXA | C5: MER | D5: + | E5: 0.5 | H5: =VC!C56 -> 0 | I5: =VC!D56 -> 0 | J5: =VC!E56 -> 0 | K5: =VC!F56 -> 0 | L5: =VC!G56 -> 0 | M5: =VC!H56 -> 0 | N5: =VC!I56 -> 0 | O5: =VC!J56 -> 0 | ... HC5: =VC!GX56 -> 0
A6: ACQUIRED | B6: aac(6')-Ib-cr, oqx, qepA, qnr, crpP | C6: CIP | D6: + | E6: 1 | H6: =VC!C57 -> 0 | I6: =VC!D57 -> 0 | J6: =VC!E57 -> 0 | K6: =VC!F57 -> 0 | L6: =VC!G57 -> 0 | M6: =VC!H57 -> 0 | N6: =VC!I57 -> 0 | O6: =VC!J57 -> 0 | ... FD6: =VC!EY57 -> 0 | FF6: =VC!FA57 -> 0 | FG6: =VC!FB57 -> 0 | FH6: =VC!FC57 -> 0 | FI6: =VC!FD57 -> 0 | FJ6: =VC!FE57 -> 0 | FK6: =VC!FF57 -> 0 | FL6: =VC!FG57 -> 0 | FM6: =VC!FH57 -> 0 | ... HC6: =VC!GX57 -> 0
A7: ACQUIRED | B7: blaNDM, blaSMP, blaGIM, blaSIM, blaVIM, blaIMP, blaKPC, blaGES, blaIMI, blaVEB, blaOXA (espectro extendido) | C7: C/T | D7: + | E7: 2/0,5 | H7: =VC!C58 -> 0 | I7: =VC!D58 -> 0 | J7: =VC!E58 -> 0 | K7: =VC!F58 -> 0 | L7: =VC!G58 -> 0 | M7: =VC!H58 -> 0 | N7: =VC!I58 -> 0 | O7: =VC!J58 -> 0 | ... HC7: =VC!GX58 -> 0
A8: PA0004 | B8: gyrB | C8: CIP | D8: + | E8: 1 | F8: Gain of function | G8: SOLO REGION QRDR (466-468) | H8: =VC_NEW!C2 -> 0 | I8: =VC_NEW!D2 -> 0 | J8: =VC_NEW!E2 -> 0 | K8: =VC_NEW!F2 -> 0 | L8: =VC_NEW!G2 -> 0 | M8: =VC_NEW!H2 -> 0 | N8: =VC_NEW!I2 -> E468D | O8: =VC_NEW!J2 -> 0 | ... HC8: =VC_NEW!GX2 -> 0
A9: PA0424 | B9: mexR | C9: CAZ | D9: + | E9: 0,5/0,25 | F9: Loss of function | G9: DOBLE SCORE | H9: =VC_NEW!C4 -> 0 | I9: =VC_NEW!D4 -> 0 | J9: =VC_NEW!E4 -> 0 | K9: =VC_NEW!F4 -> 0 | L9: =VC_NEW!G4 -> 0 | M9: =VC_NEW!H4 -> 0 | N9: =VC_NEW!I4 -> 0 | O9: =VC_NEW!J4 -> 0 | ... HC9: =VC_NEW!GX4 -> 0
A10: PA0424 | B10: mexR | C10: MER | D10: + | E10: 0,5/0,25 | F10: Loss of function | G10: DOBLE SCORE | H10: =VC_NEW!C4 -> 0 | I10: =VC_NEW!D4 -> 0 | J10: =VC_NEW!E4 -> 0 | K10: =VC_NEW!F4 -> 0 | L10: =VC_NEW!G4 -> 0 | M10: =VC_NEW!H4 -> 0 | N10: =VC_NEW!I4 -> 0 | O10: =VC_NEW!J4 -> 0 | ... HC10: =VC_NEW!GX4 -> 0
A11: PA0424 | B11: mexR | C11: CIP | D11: + | E11: 0,5/0,25 | F11: Loss of function | G11: DOBLE SCORE | H11: =VC_NEW!C4 -> 0 | I11: =VC_NEW!D4 -> 0 | J11: =VC_NEW!E4 -> 0 | K11: =VC_NEW!F4 -> 0 | L11: =VC_NEW!G4 -> 0 | M11: =VC_NEW!H4 -> 0 | N11: =VC_NEW!I4 -> 0 | O11: =VC_NEW!J4 -> 0 | ... HC11: =VC_NEW!GX4 -> 0
A12: PA0424 | B12: mexR | C12: C/T | D12: + | E12: 0,25/0,125 | F12: Loss of function | G12: DOBLE SCORE | H12: =VC_NEW!C4 -> 0 | I12: =VC_NEW!D4 -> 0 | J12: =VC_NEW!E4 -> 0 | K12: =VC_NEW!F4 -> 0 | L12: =VC_NEW!G4 -> 0 | M12: =VC_NEW!H4 -> 0 | N12: =VC_NEW!I4 -> 0 | O12: =VC_NEW!J4 -> 0 | ... HC12: =VC_NEW!GX4 -> 0
A13: PA0425 | B13: mexA | C13: CAZ | D13: - | E13: -0.5 | F13: Loss of function | G13: SOLO STOP CODON/FS | H13: =VC_NEW!C5 -> 0 | I13: =VC_NEW!D5 -> 0 | J13: =VC_NEW!E5 -> 0 | K13: =VC_NEW!F5 -> 0 | L13: =VC_NEW!G5 -> 0 | M13: =VC_NEW!H5 -> 0 | N13: =VC_NEW!I5 -> 0 | O13: =VC_NEW!J5 -> 0 | ... HC13: =VC_NEW!GX5 -> 0
A14: PA0425 | B14: mexA | C14: MER | D14: - | E14: -0.5 | F14: Loss of function | G14: SOLO STOP CODON/FS | H14: =VC_NEW!C5 -> 0 | I14: =VC_NEW!D5 -> 0 | J14: =VC_NEW!E5 -> 0 | K14: =VC_NEW!F5 -> 0 | L14: =VC_NEW!G5 -> 0 | M14: =VC_NEW!H5 -> 0 | N14: =VC_NEW!I5 -> 0 | O14: =VC_NEW!J5 -> 0 | ... HC14: =VC_NEW!GX5 -> 0
A15: PA0425 | B15: mexA | C15: CIP | D15: - | E15: -0.5 | F15: Loss of function | G15: SOLO STOP CODON/FS | H15: =VC_NEW!C5 -> 0 | I15: =VC_NEW!D5 -> 0 | J15: =VC_NEW!E5 -> 0 | K15: =VC_NEW!F5 -> 0 | L15: =VC_NEW!G5 -> 0 | M15: =VC_NEW!H5 -> 0 | N15: =VC_NEW!I5 -> 0 | O15: =VC_NEW!J5 -> 0 | ... HC15: =VC_NEW!GX5 -> 0
A16: PA0425 | B16: mexA | C16: C/T | D16: - | E16: -0.25 | F16: Loss of function | G16: SOLO STOP CODON/FS | H16: =VC_NEW!C5 -> 0 | I16: =VC_NEW!D5 -> 0 | J16: =VC_NEW!E5 -> 0 | K16: =VC_NEW!F5 -> 0 | L16: =VC_NEW!G5 -> 0 | M16: =VC_NEW!H5 -> 0 | N16: =VC_NEW!I5 -> 0 | O16: =VC_NEW!J5 -> 0 | ... HC16: =VC_NEW!GX5 -> 0
A17: PA0426 | B17: mexB | C17: CAZ | D17: - | E17: -0.5 | F17: Loss of function | G17: SOLO STOP CODON/FS | H17: =VC_NEW!C6 -> 0 | I17: =VC_NEW!D6 -> 0 | J17: =VC_NEW!E6 -> 0 | K17: =VC_NEW!F6 -> 0 | L17: =VC_NEW!G6 -> 0 | M17: =VC_NEW!H6 -> 0 | N17: =VC_NEW!I6 -> 0 | O17: =VC_NEW!J6 -> 0 | ... HC17: =VC_NEW!GX6 -> 0
A18: PA0426 | B18: mexB | C18: MER | D18: - | E18: -0.5 | F18: Loss of function | G18: SOLO STOP CODON/FS | H18: =VC_NEW!C6 -> 0 | I18: =VC_NEW!D6 -> 0 | J18: =VC_NEW!E6 -> 0 | K18: =VC_NEW!F6 -> 0 | L18: =VC_NEW!G6 -> 0 | M18: =VC_NEW!H6 -> 0 | N18: =VC_NEW!I6 -> 0 | O18: =VC_NEW!J6 -> 0 | ... HC18: =VC_NEW!GX6 -> 0
A19: PA0426 | B19: mexB | C19: CIP | D19: - | E19: -0.5 | F19: Loss of function | G19: SOLO STOP CODON/FS | H19: =VC_NEW!C6 -> 0 | I19: =VC_NEW!D6 -> 0 | J19: =VC_NEW!E6 -> 0 | K19: =VC_NEW!F6 -> 0 | L19: =VC_NEW!G6 -> 0 | M19: =VC_NEW!H6 -> 0 | N19: =VC_NEW!I6 -> 0 | O19: =VC_NEW!J6 -> 0 | ... HC19: =VC_NEW!GX6 -> 0
A20: PA0426 | B20: mexB | C20: C/T | D20: - | E20: -0.25 | F20: Loss of function | G20: SOLO STOP CODON/FS | H20: =VC_NEW!C6 -> 0 | I20: =VC_NEW!D6 -> 0 | J20: =VC_NEW!E6 -> 0 | K20: =VC_NEW!F6 -> 0 | L20: =VC_NEW!G6 -> 0 | M20: =VC_NEW!H6 -> 0 | N20: =VC_NEW!I6 -> 0 | O20: =VC_NEW!J6 -> 0 | ... HC20: =VC_NEW!GX6 -> 0
A21: PA0427 | B21: oprM | C21: TOB | D21: - | E21: -0.5 | F21: Loss of function | G21: SOLO STOP CODON/FS | H21: =VC_NEW!C7 -> 0 | I21: =VC_NEW!D7 -> 0 | J21: =VC_NEW!E7 -> 0 | K21: =VC_NEW!F7 -> 0 | L21: =VC_NEW!G7 -> 0 | M21: =VC_NEW!H7 -> 0 | N21: =VC_NEW!I7 -> 0 | O21: =VC_NEW!J7 -> 0 | ... HC21: =VC_NEW!GX7 -> 0
A22: PA0427 | B22: oprM | C22: CAZ | D22: - | E22: -0.5 | F22: Loss of function | G22: SOLO STOP CODON/FS | H22: =VC_NEW!C7 -> 0 | I22: =VC_NEW!D7 -> 0 | J22: =VC_NEW!E7 -> 0 | K22: =VC_NEW!F7 -> 0 | L22: =VC_NEW!G7 -> 0 | M22: =VC_NEW!H7 -> 0 | N22: =VC_NEW!I7 -> 0 | O22: =VC_NEW!J7 -> 0 | ... HC22: =VC_NEW!GX7 -> 0
A23: PA0427 | B23: oprM | C23: MER | D23: - | E23: -0.5 | F23: Loss of function | G23: SOLO STOP CODON/FS | H23: =VC_NEW!C7 -> 0 | I23: =VC_NEW!D7 -> 0 | J23: =VC_NEW!E7 -> 0 | K23: =VC_NEW!F7 -> 0 | L23: =VC_NEW!G7 -> 0 | M23: =VC_NEW!H7 -> 0 | N23: =VC_NEW!I7 -> 0 | O23: =VC_NEW!J7 -> 0 | ... HC23: =VC_NEW!GX7 -> 0
A24: PA0427 | B24: oprM | C24: CIP | D24: - | E24: -0.5 | F24: Loss of function | G24: SOLO STOP CODON/FS | H24: =VC_NEW!C7 -> 0 | I24: =VC_NEW!D7 -> 0 | J24: =VC_NEW!E7 -> 0 | K24: =VC_NEW!F7 -> 0 | L24: =VC_NEW!G7 -> 0 | M24: =VC_NEW!H7 -> 0 | N24: =VC_NEW!I7 -> 0 | O24: =VC_NEW!J7 -> 0 | ... HC24: =VC_NEW!GX7 -> 0
A25: PA0427 | B25: oprM | C25: C/T | D25: - | E25: -0.25 | F25: Loss of function | G25: SOLO STOP CODON/FS | H25: =VC_NEW!C7 -> 0 | I25: =VC_NEW!D7 -> 0 | J25: =VC_NEW!E7 -> 0 | K25: =VC_NEW!F7 -> 0 | L25: =VC_NEW!G7 -> 0 | M25: =VC_NEW!H7 -> 0 | N25: =VC_NEW!I7 -> 0 | O25: =VC_NEW!J7 -> 0 | ... HC25: =VC_NEW!GX7 -> 0
A26: PA0807 | B26: ampDh3 | C26: CAZ | D26: + | E26: 0,25/0,125 | F26: Loss of function | G26: DOBLE SCORE | H26: =VC_NEW!C8 -> 0 | I26: =VC_NEW!D8 -> 0 | J26: =VC_NEW!E8 -> 0 | K26: =VC_NEW!F8 -> 0 | L26: =VC_NEW!G8 -> 0 | M26: =VC_NEW!H8 -> 0 | N26: =VC_NEW!I8 -> 0 | O26: =VC_NEW!J8 -> 0 | ... HC26: =VC_NEW!GX8 -> 0
A27: PA0958 | B27: oprD | C27: MER | D27: + | E27: 0,5/0,25 | F27: Loss of function | G27: DOBLE SCORE | H27: =VC_NEW!C10 -> nt473∆14 | I27: =VC_NEW!D10 -> 0 | J27: =VC_NEW!E10 -> 0 | K27: =VC_NEW!F10 -> 0 | L27: =VC_NEW!G10 -> W138X | M27: =VC_NEW!H10 -> 0 | N27: =VC_NEW!I10 -> nt1056∆1 | O27: =VC_NEW!J10 -> 0 | ... HC27: =VC_NEW!GX10 -> 0
A28: PA1798 | B28: parS | C28: TOB | D28: + | E28: 0,5/0,25 | F28: Gain of function | G28: DOBLE SCORE (L14Q, V101M, L137P, A138T, A168V, Q232E, G361R) | H28: =VC_NEW!C14 -> L79P | I28: =VC_NEW!D14 -> 0 | J28: =VC_NEW!E14 -> V238L | K28: =VC_NEW!F14 -> 0 | L28: =VC_NEW!G14 -> 0 | M28: =VC_NEW!H14 -> 0 | N28: =VC_NEW!I14 -> L137P; V216A | O28: =VC_NEW!J14 -> 0 | ... HC28: =VC_NEW!GX14 -> 0
A29: PA1798 | B29: parS | C29: MER | D29: + | E29: 0,5/0,25 | F29: Gain of function | G29: DOBLE SCORE (L14Q, V101M, L137P, A138T, A168V, Q232E, G361R) | H29: =VC_NEW!C14 -> L79P | I29: =VC_NEW!D14 -> 0 | J29: =VC_NEW!E14 -> V238L | K29: =VC_NEW!F14 -> 0 | L29: =VC_NEW!G14 -> 0 | M29: =VC_NEW!H14 -> 0 | N29: =VC_NEW!I14 -> L137P; V216A | O29: =VC_NEW!J14 -> 0 | ... HC29: =VC_NEW!GX14 -> 0
A30: PA1798 | B30: parS | C30: CIP | D30: + | E30: 0,25/0,125 | F30: Gain of function | G30: DOBLE SCORE (L14Q, V101M, L137P, A138T, A168V, Q232E, G361R) | H30: =VC_NEW!C14 -> L79P | I30: =VC_NEW!D14 -> 0 | J30: =VC_NEW!E14 -> V238L | K30: =VC_NEW!F14 -> 0 | L30: =VC_NEW!G14 -> 0 | M30: =VC_NEW!H14 -> 0 | N30: =VC_NEW!I14 -> L137P; V216A | O30: =VC_NEW!J14 -> 0 | ... HC30: =VC_NEW!GX14 -> 0
A31: PA1799 | B31: parR | C31: TOB | D31: + | E31: 0,5/0,25 | F31: Gain of function | G31: DOBLE SCORE (M59I, E156K) | H31: =VC_NEW!C15 -> 0 | I31: =VC_NEW!D15 -> 0 | J31: =VC_NEW!E15 -> 0 | K31: =VC_NEW!F15 -> 0 | L31: =VC_NEW!G15 -> 0 | M31: =VC_NEW!H15 -> 0 | N31: =VC_NEW!I15 -> 0 | O31: =VC_NEW!J15 -> 0 | ... HC31: =VC_NEW!GX15 -> R178C
A32: PA1799 | B32: parR | C32: MER | D32: + | E32: 0,5/0,25 | F32: Gain of function | G32: DOBLE SCORE (M59I, E156K) | H32: =VC_NEW!C15 -> 0 | I32: =VC_NEW!D15 -> 0 | J32: =VC_NEW!E15 -> 0 | K32: =VC_NEW!F15 -> 0 | L32: =VC_NEW!G15 -> 0 | M32: =VC_NEW!H15 -> 0 | N32: =VC_NEW!I15 -> 0 | O32: =VC_NEW!J15 -> 0 | ... HC32: =VC_NEW!GX15 -> R178C
A33: PA1799 | B33: parR | C33: CIP | D33: + | E33: 0,25/0,125 | F33: Gain of function | G33: DOBLE SCORE (M59I, E156K) | H33: =VC_NEW!C15 -> 0 | I33: =VC_NEW!D15 -> 0 | J33: =VC_NEW!E15 -> 0 | K33: =VC_NEW!F15 -> 0 | L33: =VC_NEW!G15 -> 0 | M33: =VC_NEW!H15 -> 0 | N33: =VC_NEW!I15 -> 0 | O33: =VC_NEW!J15 -> 0 | ... HC33: =VC_NEW!GX15 -> R178C
A34: PA2018 | B34: mexY | C34: TOB | D34: - | E34: -0.5 | F34: Loss of function | G34: SÓLO STOP CODON/ FS | H34: =VC_NEW!C16 -> D428N | I34: =VC_NEW!D16 -> 0 | J34: =VC_NEW!E16 -> 0 | K34: =VC_NEW!F16 -> A708T | L34: =VC_NEW!G16 -> D428N | M34: =VC_NEW!H16 -> L239P | N34: =VC_NEW!I16 -> 0 | O34: =VC_NEW!J16 -> 0 | ... HC34: =VC_NEW!GX16 -> 0
A35: PA2018 | B35: mexY | C35: MER | D35: - | E35: -0.5 | F35: Loss of function | G35: SÓLO STOP CODON/ FS | H35: =VC_NEW!C16 -> D428N | I35: =VC_NEW!D16 -> 0 | J35: =VC_NEW!E16 -> 0 | K35: =VC_NEW!F16 -> A708T | L35: =VC_NEW!G16 -> D428N | M35: =VC_NEW!H16 -> L239P | N35: =VC_NEW!I16 -> 0 | O35: =VC_NEW!J16 -> 0 | ... HC35: =VC_NEW!GX16 -> 0
A36: PA2018 | B36: mexY | C36: CIP | D36: - | E36: -0.25 | F36: Loss of function | G36: SÓLO STOP CODON/ FS | H36: =VC_NEW!C16 -> D428N | I36: =VC_NEW!D16 -> 0 | J36: =VC_NEW!E16 -> 0 | K36: =VC_NEW!F16 -> A708T | L36: =VC_NEW!G16 -> D428N | M36: =VC_NEW!H16 -> L239P | N36: =VC_NEW!I16 -> 0 | O36: =VC_NEW!J16 -> 0 | ... HC36: =VC_NEW!GX16 -> 0
A37: PA2019 | B37: mexX | C37: TOB | D37: - | E37: -0.5 | F37: Loss of function | G37: SÓLO STOP CODON/ FS | H37: =VC_NEW!C31 -> 0 | I37: =VC_NEW!D17 -> 0 | J37: =VC_NEW!E17 -> 0 | K37: =VC_NEW!F17 -> 0 | L37: =VC_NEW!G17 -> 0 | M37: =VC_NEW!H17 -> 0 | N37: =VC_NEW!I17 -> 0 | O37: =VC_NEW!J17 -> 0 | P37: =VC_NEW!K17 -> S320P | ... HC37: =VC_NEW!GX17 -> 0
A38: PA2019 | B38: mexX | C38: MER | D38: - | E38: -0.5 | F38: Loss of function | G38: SÓLO STOP CODON/ FS | H38: =VC_NEW!C32 -> 0 | I38: =VC_NEW!D17 -> 0 | J38: =VC_NEW!E17 -> 0 | K38: =VC_NEW!F17 -> 0 | L38: =VC_NEW!G17 -> 0 | M38: =VC_NEW!H17 -> 0 | N38: =VC_NEW!I17 -> 0 | O38: =VC_NEW!J17 -> 0 | P38: =VC_NEW!K17 -> S320P | ... HC38: =VC_NEW!GX17 -> 0
A39: PA2019 | B39: mexX | C39: CIP | D39: - | E39: -0.25 | F39: Loss of function | G39: SÓLO STOP CODON/ FS | H39: =VC_NEW!C33 -> 0 | I39: =VC_NEW!D17 -> 0 | J39: =VC_NEW!E17 -> 0 | K39: =VC_NEW!F17 -> 0 | L39: =VC_NEW!G17 -> 0 | M39: =VC_NEW!H17 -> 0 | N39: =VC_NEW!I17 -> 0 | O39: =VC_NEW!J17 -> 0 | P39: =VC_NEW!K17 -> S320P | ... HC39: =VC_NEW!GX17 -> 0
A40: PA2020 | B40: mexZ | C40: TOB | D40: + | E40: 0,5/0,25 | F40: Loss of function | G40: DOBLE SCORE | H40: =VC_NEW!C18 -> 0 | I40: =VC_NEW!D18 -> D83E | J40: =VC_NEW!E18 -> 0 | K40: =VC_NEW!F18 -> 0 | L40: =VC_NEW!G18 -> aa103∆1 | M40: =VC_NEW!H18 -> 0 | N40: =VC_NEW!I18 -> aa163InsY | O40: =VC_NEW!J18 -> 0 | ... HC40: =VC_NEW!GX18 -> 0
...

Sheet VC_NEW
A1: LOCUS | B1: GENE | C1: AND01-001 | D1: AND01-004 | E1: AND01-005 | F1: AND01-006 | G1: AND02-001 | H1: AND02-002 | I1: AND02-003 | J1: AND02-006 | K1: AND03-001 | L1: AND03-003 | M1: AND03-009 | N1: AND03-012 | O1: AND04-001 | P1: AND04-002 | Q1: AND04-003 | R1: AND04-004A | S1: AND05-004 | T1: AND05-005 | U1: AND05-008 | V1: AND05-009 | W1: AND06-001 | X1: AND06-002 | Y1: AND06-003 | Z1: AND06-006 | AA1: AND07-001 | AB1: AND07-002 | AC1: AND07-003 | AD1: AND07-005 | AE1: ARA01-001 | AF1: ARA01-002 | AG1: ARA01-003 | AH1: ARA01-006 | AI1: ARA02-001 | AJ1: ARA02-002 | AK1: ARA02-005 | AL1: ARA02-007 | AM1: ARA03-001 | AN1: ARA03-002 | AO1: ARA03-003 | AP1: ARA03-004 | AQ1: AST01-001 | AR1: AST01-003 | AS1: AST01-005 | AT1: AST01-006 | AU1: BAL01-001 | AV1: BAL01-003 | AW1: BAL01-004 | AX1: BAL01-006 | AY1: BAL02-001 | AZ1: BAL02-005 | BA1: BAL02-006 | BB1: BAL02-009 | BC1: BAL03-001 | BD1: BAL03-002 | BE1: BAL03-003 | BF1: BAL03-006 | BG1: BAL04-001 | BH1: BAL04-002 | BI1: BAL04-003 | BJ1: BAL04-004 | BK1: CAN01-001 | BL1: CAN01-002 | BM1: CAN01-003 | BN1: CAN01-004 | BO1: CAT01-001 | BP1: CAT01-004 | BQ1: CAT01-005 | BR1: CAT01-007 | BS1: CAT02-001 | BT1: CAT02-002 | BU1: CAT02-003 | BV1: CAT02-004 | BW1: CAT03-001 | BX1: CAT03-002 | BY1: CAT03-004 | BZ1: CAT03-005 | CA1: CAT04-001 | CB1: CAT04-002 | CC1: CAT04-003 | CD1: CAT04-004 | CE1: CAT05-001 | CF1: CAT05-002 | CG1: CAT05-003 | CH1: CAT05-004 | CI1: CAT06-001 | CJ1: CAT06-004 | CK1: CAT06-005 | CL1: CAT06-008 | CM1: CAT07-001 | CN1: CAT07-002 | CO1: CAT07-003 | CP1: CAT07-005 | CQ1: CAT08-013 | CR1: CAT08-014 | CS1: CAT08-015 | CT1: CAT08-016 | CU1: CAT09-001 | CV1: CAT09-002 | CW1: CAT09-003 | CX1: CAT09-004 | CY1: CLE01-003 | CZ1: CLE01-006 | DA1: CLE01-007 | DB1: CLE01-008 | DC1: CLE02-001 | DD1: CLE02-002 | DE1: CLE02-004 | DF1: CLE02-006 | DG1: CLE03-003 | DH1: CLE03-004 | DI1: CLE03-005 | DJ1: CLE03-006 | DK1: CLM01-001 | DL1: CLM01-002 | DM1: CLM01-003 | DN1: CLM01-004 | DO1: CLM02-004 | DP1: CLM02-005 | DQ1: CLM02-013 | DR1: CLM02-014 | DS1: CVA01-001 | DT1: CVA01-002 | DU1: CVA01-005 | DV1: CVA01-006 | DW1: CVA02-001 | DX1: CVA02-002 | DY1: CVA02-003 | DZ1: CVA02-005 | EA1: CVA03-001 | EB1: CVA03-002 | EC1: CVA03-004 | ED1: CVA03-006 | EE1: EXT01-001 | EF1: EXT01-003 | EG1: EXT01-004 | EH1: EXT01-005 | EI1: GAL01-001 | EJ1: GAL01-002 | EK1: GAL01-003 | EL1: GAL01-012 | EM1: GAL02-001 | EN1: GAL02-002 | EO1: GAL02-004 | EP1: GAL02-006 | EQ1: GAL03-002 | ER1: GAL03-003 | ES1: GAL03-004 | ET1: GAL03-005 | EU1: GAL04-001 | EV1: GAL04-002 | EW1: GAL04-004 | EX1: GAL04-005 | EY1: GAL05-002 | EZ1: GAL05-003 | FA1: GAL05-004 | FB1: GAL05-005 | FC1: GAL06-001 | FD1: GAL06-002 | FE1: GAL06-003 | FF1: GAL06-004 | FG1: ICA01-001 | FH1: ICA01-002 | FI1: ICA01-003 | FJ1: ICA01-004 | FK1: LRJ01-002 | FL1: LRJ01-005 | FM1: LRJ01-010 | FN1: LRJ01-012 | FO1: MAD01-001 | FP1: MAD01-002 | FQ1: MAD01-004 | FR1: MAD01-005 | FS1: MAD02-001 | FT1: MAD02-002 | FU1: MAD02-004 | FV1: MAD02-005 | FW1: MAD03-001 | FX1: MAD03-002 | FY1: MAD03-004 | FZ1: MAD03-005 | GA1: MAD04-001 | GB1: MAD04-002 | GC1: MAD04-003 | GD1: MAD04-004 | GE1: MAD05-003 | GF1: MAD05-008 | GG1: MAD05-009 | GH1: MAD05-011 | GI1: MAD06-001 | GJ1: MAD06-002 | GK1: MAD06-004 | GL1: MAD06-005 | GM1: MUR01-001 | GN1: MUR01-002 | GO1: MUR01-003 | GP1: MUR01-004 | GQ1: NAV01-001 | GR1: NAV01-004 | GS1: NAV01-005 | GT1: NAV01-012 | GU1: PVA01-003 | GV1: PVA01-006 | GW1: PVA01-007 | GX1: PVA01-011
A2: PA0004 | B2: gyrB | I2: E468D | AF2: S466F | BE2: S466Y | CN2: E468D | DM2: S466Y | DP2: E468D | DR2: E468D | DY2: S466F | EG2: S466Y | EW2: S466F | EZ2: E468D | FP2: E468D | FW2: E468D | GG2: S466F
A3: PA0005 | B3: lptA | ER3: R66H
A4: PA0424 | B4: mexR | W4: S92N | X4: aa11∆4 | AF4: L102P | AJ4: nt402∆11 | AW4: L95F | BI4: nt81InsT | BV4: nt266InsG | CA4: R73L | CN4: L95F | CR4: nt161InsC | DA4: R82H | EF4: nt217∆1 | ER4: N79S | FM4: Q49X | FR4: aa90∆4 | GW4: nt492InsACCC
A5: PA0425 | B5: mexA | AS5: I63V | BH5: K86E | CI5: Q143P | CJ5: N269S | CS5: A33T | DF5: K86E | DL5: K76Q | DP5: Q104X | DY5: E53X | EA5: A111T | EB5: A117V | EM5: R326Q | EQ5: K86E | GP5: N269S
A6: PA0426 | B6: mexB | AH6: V1042A | BJ6: E422X | BL6: Q319X | CF6: nt1135∆1 | CL6: A735D | DV6: nt881InsGG | EB6: nt2936∆1 | EO6: nt3018∆5 | ER6: A707S; I963V | ET6: T98A | EW6: G860D | GL6: A539T | GS6: P190L
A7: PA0427 | B7: oprM | BI7: nt1451InsC | CK7: T198P | CQ7: T180I | DM7: nt501∆5 | ER7: Q265E
A8: PA0807 | B8: ampDh3 | BB8: P55S | DP8: nt410∆1 | DR8: nt410∆1 | ED8: Y207X | EZ8: L246P
A9: PA0869 | B9: PBP7 | E9: V61A | H9: V171I | M9: G137D | AS9: T200I | BI9: V305M | BL9: R112G | CS9: T200I; A290T | CW9: R175P | ER9: G30R | FF9: P88S | GN9: V9A | GQ9: H205N | GS9: V171I
A10: PA0958a | B10: oprD | C10: nt473∆14 | G10: W138X | I10: nt1056∆1 | V10: F321V, N430Y | Z10: nt1185∆1 | AG10: nt1206InsC | AH10: aa397∆9 | AN10: nt1206InsC | AO10: nt209∆10 | AQ10: D43N | AV10: Q142X | AW10: nt1206InsC | AX10: Q142X | BI10: nt438InsC | BJ10: W339X | BL10: nt175∆11 | BM10: L432P | BN10: nt199∆1 | BY10: Q142X | CA10: nt1206InsC | CE10: Q142X | CF10: Q142X | CH10: W277X | CK10: Q142X | CL10: Q142X | DE10: nt350InsC | DP10: W415X | DR10: W415X | DS10: T103S, K115T, F170L, nt169∆1, nt175InsA | DV10: nt55InsGCACT | DW10: D43N, M135I, E185Q, P186G, V189T, S267A, T276A, G310E, A315G, L347M, L359V, Q422E | DZ10: nt55InsGCACT | EC10: nt1206InsC | EE10: Y225X | EO10: L407P | EP10: S408P | EV10: W417X | EZ10: Q158X | FF10: Q422X | FI10: M135I | FJ10: D43N | FV10: W277X | GG10: W339G | GL10: D43N | GS10: nt742∆1 | GT10: nt991InsAC | GW10: Q142X
A11: PA1179 | B11: phoP | BK11: E35G | EN11: G70D
A12: PA1180 | B12: phoQ | AY12: R240C | BK12: S300R | BX12: S300R | CN12: A23V | CP12: Q308R | CT12: S300R | DY12: D326N | EH12: S300R | EJ12: S157T | ER12: D90E; E267Q; V369L | EW12: S300R | EX12: R3C
A13: PA1777 | B13: oprF | DB13: D64Y | DM13: nt164∆1
A14: PA1798 | B14: parS | C14: L79P | E14: V238L | I14: L137P; V216A | M14: S352I | Z14: A345T | AJ14: R83K; V216A | BE14: R385H | BK14: aa118∆4 | BM14: L137P; nt998∆1 | BS14: G303R | CM14: S352I | DS14: V238L | DT14: Y73C | DY14: S33R | ED14: A293V | EM14: L346P | EZ14: V216A | FD14: S277N | FG14: R7H | FS14: D348N | FX14: Q349K | FZ14: V238L | GC14: D351N | GE14: A395T | GF14: V152A | GP14: A29V | GT14: L137P
A15: PA1799 | B15: parR | BO15: L90I | DJ15: aa214∆1 | FN15: P128S | GI15: V55I; I80L | GX15: R178C
A16: PA2018 | B16: mexY | C16: D428N | F16: A708T | G16: D428N | H16: L239P | K16: T742I | O16: A131T; P1032S | U16: V875M; N1036S | Z16: N709S | AC16: A586T; N709H | AH16: R706H | AS16: A772T | BB16: R251H; I543V | BH16: P1032S | BL16: G530S | BM16: G530S | CY16: A285T | DF16: P1032S | DI16: DELETED | DN16: D628H | DU16: R1024S | DW16: R706H | DY16: T472P; P1032S | ED16: E505G | EG16: D724V | EQ16: P1032S | ER16: S48N; T472A; D502G; R519H; Q843R; I849V; A865D | FF16: A772T | FI16: R706H | FJ16: D428N | FN16: I531T | FR16: A772T | GF16: T238I | GI16: G1002A | GL16: T393A | GO16: A527V;V548M | GT16: G530S | GV16: G530S
A17: PA2019 | B17: mexX | K17: S320P | M17: I212L | W17: S382G | AC17: S382G | BB17: A38T | BC17: S382G | BI17: A375P; A383P | CJ17: V376M | DI17: DELETED | DU17: L154Q | ED17: R151H | EL17: Y255X | ER17: A15T; A48V; E142K; D384G | FN17: Q4H | FX17: W358C | FY17: Q396X | GG17: W358C | GP17: R69Q
A18: PA2020 | B18: mexZ | D18: D83E | G18: aa103∆1 | I18: aa163InsY | X18: T12N | AG18: W185X | AL18: nt484InsC | AV18: G195D | AX18: G195D | AZ18: aa187∆6 | BB18: G68D | BD18: G195D | BL18: Q140K | BN18: G195D | BO18: nt526∆8 | BR18: V105G | BY18: G195D | CE18: G195D | CF18: G195D | CH18: V105G | CK18: G195D | CL18: G195D | CU18: aa48∆9 | CW18: H51D | DG18: R45C | DH18: nt386∆1 | DI18: DELETED | DL18: D83E | DR18: G195D | DV18: G195D | DX18: L37P | DY18: nt491∆10 | DZ18: G195D | EB18: Q132X | EC18: nt320∆16 | EN18: Y204X | ER18: F192L | EU18: nt367∆10 | EV18: nt100∆1 | EZ18: aa163InsY | FD18: A47V | FL18: G195D | FN18: A81V; Q134R | FP18: Q132P | FV18: G195D | GG18: A88P | GH18: G195D | GI18: nt227∆1 | GS18: R104W | GW18: G195D
A19: PA2023 | B19: galU | CF19: nt61∆5 | DD19: ∆63nt | DI19: DELETED | DX19: G175S | EA19: aa207∆4 | EB19: Y12C; L21R; G56S | EN19: C242X | FE19: nt679∆1 | GS19: F248S
